<?xml version="1.0"?>
<robot name="jakes_pendulum">

	<!-- * * * Link Definitions * * * -->

    <link name="base_link">
		<visual>
		    <origin xyz="0 0 0" rpy="0 0 0"/>
			<geometry>
				<cylinder radius="0.025" length="0.01"/>
			</geometry>
			<material name="Cyan1">
	       		<color rgba="0 1 1 1.0"/>
           	</material>
		</visual>
		<collision>
		    <origin xyz="0 0 0" rpy="0 0 0"/>
			<geometry>
				<cylinder radius="0.025" length="0.01"/>
			</geometry>
		</collision>	
	</link>
		
	<link name="upper_arm">
        <visual>
		    <origin xyz="0.5 0 0" rpy="0 1.571 0"/>
			<geometry>
				<cylinder radius="0.025" length="1.0"/>
			</geometry>
			<material name="Blue2">
	       		<color rgba="0 0.5 0 1.0"/>
	        </material>
	    </visual>
		<collision>
            <origin xyz="0.5 0 0" rpy="0 1.571 0"/>
            <geometry>
                <cylinder radius="0.025" length="1.0"/>
            </geometry>
        </collision>
	</link>

	<link name="end_ball">
		<visual>
		    <origin xyz="0.1 0 0" rpy="0 0 0"/>
			<geometry>
				<sphere radius="0.1"/>
			</geometry>
			<material name="Cyan2">
	       		<color rgba="1 0 0.7 1.0"/>
	        </material>
		</visual>
		<collision>
           	<origin xyz="0.1 0 0" rpy="0 0 0"/>
			<geometry>
				<sphere radius="0.1"/>
			</geometry>
        </collision>	
	</link>

<!--    
    <link name="lower_arm">
		<visual>
		    <origin xyz="0.5 0 0" rpy="0 1.571 0"/>
			<geometry>
				<cylinder radius="0.025" length="1.0"/>
			</geometry>
			<material name="Cyan2">
	       		<color rgba="1 0 0.7 1.0"/>
	        </material>
		</visual>
		<collision>
            <origin xyz="0.5 0 0" rpy="0 1.571 0"/>
            <geometry>
                <cylinder radius="0.025" length="1.0"/>
            </geometry>
        </collision>	
	</link>
-->
  	  	

	<!-- * * * Joint Definitions * * * -->
	
	<joint name="shoulder_joint" type="revolute">
    	<parent link="base_link"/>
    	<child link="upper_arm"/>
    	<origin xyz="0.0 0 0.0" rpy="0 0 0"/>
        <limit lower="-10" upper="10" effort="10" velocity="3.4"/>
        <axis xyz="0 0 1"/>
	</joint>
	
	<joint name="end_joint" type="fixed">
    	<parent link="upper_arm"/>
    	<child link="end_ball"/>
    	<origin xyz="1.0 0 0.0" rpy="0 0 0"/>
	</joint>
<!--
    <joint name="elbow_joint" type="revolute">
    	<parent link="upper_arm"/>
    	<child link="lower_arm"/>
    	<origin xyz="1 0 0.0" rpy="0 0 0"/>
        <limit lower="-10" upper="10" effort="10" velocity="3"/>
        <axis xyz="0 0 1"/>
	</joint>
	
-->
</robot>
